<?xml version="1.0" encoding="UTF-8"?>
<!-- Generated by org.testng.reporters.JUnitXMLReporter -->
<testsuite hostname="manjunathspc" ignored="0" name="Upp user flow" tests="1" failures="1" timestamp="20 Jan 2020 12:17:16 GMT" time="28.276" errors="0">
  <testcase name="@AfterMethod closebrowser" time="0.511" classname="base.SuperTestNG">
    <failure type="java.lang.NullPointerException">
      <![CDATA[java.lang.NullPointerException
at base.SuperTestNG.closebrowser(SuperTestNG.java:182)
at java.util.concurrent.FutureTask.run(Unknown Source)
at java.util.concurrent.ThreadPoolExecutor.runWorker(Unknown Source)
at java.util.concurrent.ThreadPoolExecutor$Worker.run(Unknown Source)
at java.lang.Thread.run(Unknown Source)
... Removed 19 stack frames]]>
    </failure>
  </testcase> <!-- @AfterMethod closebrowser -->
  <testcase name="UPP" time="4.851" classname="WH.Upp_Login">
    <failure type="java.lang.AssertionError" message="expected [https://india.unicityportal.com/test_warehouseorder/upppayments] but found [https://india.unicityportal.com/test_warehouseorder/auth/login]">
      <![CDATA[java.lang.AssertionError: expected [https://india.unicityportal.com/test_warehouseorder/upppayments] but found [https://india.unicityportal.com/test_warehouseorder/auth/login]
at pages.Landingpage.UppLogin(Landingpage.java:59)
at WH.Upp_Login.UPP(Upp_Login.java:37)
at java.util.concurrent.FutureTask.run(Unknown Source)
at java.util.concurrent.ThreadPoolExecutor.runWorker(Unknown Source)
at java.util.concurrent.ThreadPoolExecutor$Worker.run(Unknown Source)
at java.lang.Thread.run(Unknown Source)
... Removed 22 stack frames]]>
    </failure>
  </testcase> <!-- UPP -->
</testsuite> <!-- Upp user flow -->
